Workbook

Sheet LISTA 268
A1: RALUX SAIC
A2: LISTA DE PRECIOS Nº 268
J3: 46220
A4: ART | B4: PRECIO | C4: ART | D4: PRECIO | E4: ART | F4: PRECIO | G4: ART | H4: PRECIO | I4: ART | J4: PRECIO
A5: 103 | B5: 21958 | C5: 244M | D5: 5957 | E5: 828 | F5: 28779 | G5: B-8408 | H5: 32919 | I5: D-8558 | J5: 17515
A6: 104 | B6: 20704 | C6: 253 | D6: 16970 | E6: 831 | F6: 61655 | G6: B-8409 | H6: 28736 | I6: D-8559 | J6: 18679
A7: 106 | B7: 21634 | C7: 256 | D7: 17221 | E7: 832 | F7: 40202 | G7: B-8412 | H7: 32521 | I7: R-8560 | J7: 14647
A8: 107 | B8: 22764 | C8: 257 | D8: 17221 | E8: 901 | F8: 2393 | G8: D-8418 | H8: 16977 | I8: R-8561 | J8: 15296
A9: 109 | B9: 24298 | C9: 266E | D9: 18411 | E9: 902 | F9: 1634 | G9: R-8421 | H9: 10953 | I9: R-8563 | J9: 12715
A10: 110 | B10: 23693 | C10: 270 | D10: 16985 | E10: 903 | F10: 1222 | G10: R-8422 | H10: 9828 | I10: R-8564 | J10: 11092
A11: 111 | B11: 23737 | C11: 271 | D11: 16555 | E11: 1006605 | F11: 163282 | G11: T-8426 | H11: 31015 | I11: R-8565 | J11: 10206
A12: 112 | B12: 24462 | C12: 272 | D12: 16645 | E12: 1111 | F12: 35797 | G12: R-8427 | H12: 35728 | I12: R-8568 | J12: 10400
A13: 113 | B13: 26261 | C13: 273 | D13: 16147 | E13: 1121 | F13: 37463 | G13: T-8428 | H13: 29977 | I13: T-8569 | J13: 85267
A14: 128 | B14: 11191 | C14: 274 | D14: 16193 | E14: 1140 | F14: 32023 | G14: B-8437 | H14: 45812 | I14: R-8570 | J14: 10654
A15: 129 | B15: 11525 | C15: 275 | D15: 16364 | E15: 1150 | F15: 34032 | G15: R-8440 | H15: 9055 | I15: R-8571 | J15: 9828
A16: 130 | B16: 11136 | C16: 276 | D16: 16284 | E16: 1150A | F16: 37463 | G16: D-8444 | H16: 16517 | I16: R-8572 | J16: 14226
A17: 132 | B17: 8893 | C17: 277 | D17: 16853 | E17: 1150E | F17: 35797 | G17: T-8445-R | H17: 64751 | I17: T-8573 | J17: 14583
A18: 133 | B18: 9484 | C18: 278 | D18: 17362 | E18: 1303 | F18: 12710 | G18: T-8452 | H18: 45070 | I18: D-8574 | J18: 18937
A19: 134 | B19: 10042 | C19: 279 | D19: 19631 | E19: 1305 | F19: 12820 | G19: R-8454 | H19: 10905 | I19: R-8575 | J19: 9455
A20: 135 | B20: 9716 | C20: 280 | D20: 17776 | E20: 1308 | F20: 10046 | G20: R-8455 | H20: 9232 | I20: T-8576 | J20: 51273
A21: 136 | B21: 11006 | C21: 281 | D21: 17055 | E21: 1309 | F21: 11774 | G21: R-8456 | H21: 8238 | I21: R-8578 | J21: 8466
A22: 137 | B22: 11498 | C22: 282 | D22: 19053 | E22: 5001R | F22: 50529 | G22: R-8457 | H22: 8681 | I22: R-8579 | J22: 9830
A23: 138 | B23: 9086 | C23: 283 | D23: 16441 | E23: 5002 | F23: 52527 | G23: R-8458 | H23: 9365 | I23: R-8581 | J23: 18406
A24: 139 | B24: 10051 | C24: 284 | D24: 19129 | E24: 5003R | F24: 49939 | G24: R-8459 | H24: 9529 | I24: T-8582 | J24: 46967
A25: 140 | B25: 10479 | C25: 285 | D25: 18434 | E25: 5004 | F25: 52527 | G25: R-8460 | H25: 11686 | I25: T-8589 | J25: 56180
A26: 141 | B26: 10272 | C26: 286 | D26: 17516 | E26: 5005 | F26: 52527 | G26: R-8461 | H26: 11686 | I26: R-8590 | J26: 9793
A27: 142 | B27: 10198 | C27: 287 | D27: 17070 | E27: 5006 | F27: 51430 | G27: R-8462 | H27: 11463 | I27: R-8596 | J27: 14249
A28: 143 | B28: 10064 | C28: 288 | D28: 16894 | E28: 5007R | F28: 51802 | G28: R-8463 | H28: 12192 | I28: R-8599 | J28: 10297
A29: 144 | B29: 10302 | C29: 289 | D29: 17362 | E29: 5008 | F29: 53651 | G29: R-8464 | H29: 8791 | I29: R-8653 | J29: 15879
A30: 149R | B30: 5444 | C30: 291 | D30: 18321 | E30: 5009 | F30: 53652 | G30: R-8465 | H30: 10177 | I30: R-8654 | J30: 10167
A31: 152 | B31: 10427 | C31: 292 | D31: 21520 | E31: 5010 | F31: 59201 | G31: R-8467 | H31: 4231 | I31: T-8656 | J31: 31855
A32: 153 | B32: 10198 | C32: 293 | D32: 23663 | E32: 5011 | F32: 55503 | G32: R-8468 | H32: 9593 | I32: T-8658 | J32: 53474
A33: 156 | B33: 8374 | C33: 294 | D33: 21877 | E33: T-5800 | F33: 21382 | G33: R-8477 | H33: 9909 | I33: R-8659 | J33: 12009
A34: 157PLUS | B34: 5236 | C34: 295 | D34: 16760 | E34: T-8095 | F34: 23370 | G34: R-8481 | H34: 12652 | I34: T-8660 | J34: 39293
A35: 158 | B35: 6484 | C35: 296 | D35: 29236 | E35: R-8130 | F35: 9502 | G35: R-8484 | H35: 14808 | I35: R-8661 | J35: 11015
A36: 160/60 | B36: 7131 | C36: 297 | D36: 17281 | E36: R-8131 | F36: 9523 | G36: R-8485 | H36: 17995 | I36: D-8662 | J36: 17170
A37: 161 | B37: 9886 | C37: 298 | D37: 17273 | E37: R-8133 | F37: 10584 | G37: R-8486 | H37: 17437 | I37: T-8664 | J37: 23342
A38: 162 | B38: 10108 | C38: 299 | D38: 17348 | E38: R-8135 | F38: 10980 | G38: T-8487 | H38: 61049 | I38: R-8665 | J38: 9454
A39: 163 | B39: 10571 | C39: 407 | D39: 22421 | E39: D-8175 | F39: 19759 | G39: D-8489 | H39: 16092 | I39: R-8666 | J39: 9731
A40: 164 | B40: 9595 | C40: 408 | D40: 25878 | E40: D-8176 | F40: 22012 | G40: B-8500 | H40: 26670 | I40: T-8667 | J40: 42420
...

Sheet BO
A1: RALUX SAIC
A2: LISTA DE PRECIOS Nº 268
J3: 46220
A4: ART | B4: PRECIO | C4: ART | D4: PRECIO | E4: ART | F4: PRECIO | G4: ART | H4: PRECIO | I4: ART | J4: PRECIO
A5: 103 | B5: =+VLOOKUP(A5,COLUMNA!$B$5:$C$1691,2,0) -> 21958 | C5: 244M | D5: =+VLOOKUP(C5,COLUMNA!$B$5:$C$1691,2,0) -> 5957 | E5: 828 | F5: 28779 | G5: B-8408 | H5: =+VLOOKUP(G5,COLUMNA!$B$5:$C$1691,2,0) -> 32919 | I5: D-8558 | J5: =+VLOOKUP(I5,COLUMNA!$B$5:$C$1691,2,0) -> 17515
A6: 104 | B6: =+VLOOKUP(A6,COLUMNA!$B$5:$C$1691,2,0) -> 20704 | C6: 253 | D6: =+VLOOKUP(C6,COLUMNA!$B$5:$C$1691,2,0) -> 16970 | E6: 831 | F6: 61655 | G6: B-8409 | H6: =+VLOOKUP(G6,COLUMNA!$B$5:$C$1691,2,0) -> 28736 | I6: D-8559 | J6: =+VLOOKUP(I6,COLUMNA!$B$5:$C$1691,2,0) -> 18679
A7: 106 | B7: =+VLOOKUP(A7,COLUMNA!$B$5:$C$1691,2,0) -> 21634 | C7: 256 | D7: =+VLOOKUP(C7,COLUMNA!$B$5:$C$1691,2,0) -> 17221 | E7: 832 | F7: 40202 | G7: B-8412 | H7: =+VLOOKUP(G7,COLUMNA!$B$5:$C$1691,2,0) -> 32521 | I7: R-8560 | J7: =+VLOOKUP(I7,COLUMNA!$B$5:$C$1691,2,0) -> 14647
A8: 107 | B8: =+VLOOKUP(A8,COLUMNA!$B$5:$C$1691,2,0) -> 22764 | C8: 257 | D8: =+VLOOKUP(C8,COLUMNA!$B$5:$C$1691,2,0) -> 17221 | E8: 901 | F8: =+VLOOKUP(E8,COLUMNA!$B$5:$C$1691,2,0) -> 2393 | G8: D-8418 | H8: =+VLOOKUP(G8,COLUMNA!$B$5:$C$1691,2,0) -> 16977 | I8: R-8561 | J8: =+VLOOKUP(I8,COLUMNA!$B$5:$C$1691,2,0) -> 15296
A9: 109 | B9: =+VLOOKUP(A9,COLUMNA!$B$5:$C$1691,2,0) -> 24298 | C9: 266E | D9: =+VLOOKUP(C9,COLUMNA!$B$5:$C$1691,2,0) -> 18411 | E9: 902 | F9: =+VLOOKUP(E9,COLUMNA!$B$5:$C$1691,2,0) -> 1634 | G9: R-8421 | H9: =+VLOOKUP(G9,COLUMNA!$B$5:$C$1691,2,0) -> 10953 | I9: R-8563 | J9: =+VLOOKUP(I9,COLUMNA!$B$5:$C$1691,2,0) -> 12715
A10: 110 | B10: =+VLOOKUP(A10,COLUMNA!$B$5:$C$1691,2,0) -> 23693 | C10: 270 | D10: =+VLOOKUP(C10,COLUMNA!$B$5:$C$1691,2,0) -> 16985 | E10: 903 | F10: =+VLOOKUP(E10,COLUMNA!$B$5:$C$1691,2,0) -> 1222 | G10: R-8422 | H10: =+VLOOKUP(G10,COLUMNA!$B$5:$C$1691,2,0) -> 9828 | I10: R-8564 | J10: =+VLOOKUP(I10,COLUMNA!$B$5:$C$1691,2,0) -> 11092
A11: 111 | B11: =+VLOOKUP(A11,COLUMNA!$B$5:$C$1691,2,0) -> 23737 | C11: 271 | D11: =+VLOOKUP(C11,COLUMNA!$B$5:$C$1691,2,0) -> 16555 | E11: 1006605 | F11: =+VLOOKUP(E11,COLUMNA!$B$5:$C$1691,2,0) -> 163282 | G11: T-8426 | H11: =+VLOOKUP(G11,COLUMNA!$B$5:$C$1691,2,0) -> 31015 | I11: R-8565 | J11: =+VLOOKUP(I11,COLUMNA!$B$5:$C$1691,2,0) -> 10206
A12: 112 | B12: =+VLOOKUP(A12,COLUMNA!$B$5:$C$1691,2,0) -> 24462 | C12: 272 | D12: =+VLOOKUP(C12,COLUMNA!$B$5:$C$1691,2,0) -> 16645 | E12: 1111 | F12: =+VLOOKUP(E12,COLUMNA!$B$5:$C$1691,2,0) -> 35797 | G12: R-8427 | H12: =+VLOOKUP(G12,COLUMNA!$B$5:$C$1691,2,0) -> 35728 | I12: R-8568 | J12: =+VLOOKUP(I12,COLUMNA!$B$5:$C$1691,2,0) -> 10400
A13: 113 | B13: =+VLOOKUP(A13,COLUMNA!$B$5:$C$1691,2,0) -> 26261 | C13: 273 | D13: =+VLOOKUP(C13,COLUMNA!$B$5:$C$1691,2,0) -> 16147 | E13: 1121 | F13: =+VLOOKUP(E13,COLUMNA!$B$5:$C$1691,2,0) -> 37463 | G13: T-8428 | H13: =+VLOOKUP(G13,COLUMNA!$B$5:$C$1691,2,0) -> 29977 | I13: T-8569 | J13: =+VLOOKUP(I13,COLUMNA!$B$5:$C$1691,2,0) -> 85267
A14: 128 | B14: 11191 | C14: 274 | D14: =+VLOOKUP(C14,COLUMNA!$B$5:$C$1691,2,0) -> 16193 | E14: 1140 | F14: =+VLOOKUP(E14,COLUMNA!$B$5:$C$1691,2,0) -> 32023 | G14: B-8437 | H14: =+VLOOKUP(G14,COLUMNA!$B$5:$C$1691,2,0) -> 45812 | I14: R-8570 | J14: =+VLOOKUP(I14,COLUMNA!$B$5:$C$1691,2,0) -> 10654
A15: 129 | B15: 11525 | C15: 275 | D15: =+VLOOKUP(C15,COLUMNA!$B$5:$C$1691,2,0) -> 16364 | E15: 1150 | F15: =+VLOOKUP(E15,COLUMNA!$B$5:$C$1691,2,0) -> 34032 | G15: R-8440 | H15: =+VLOOKUP(G15,COLUMNA!$B$5:$C$1691,2,0) -> 9055 | I15: R-8571 | J15: =+VLOOKUP(I15,COLUMNA!$B$5:$C$1691,2,0) -> 9828
A16: 130 | B16: =+VLOOKUP(A16,COLUMNA!$B$5:$C$1691,2,0) -> 11136 | C16: 276 | D16: =+VLOOKUP(C16,COLUMNA!$B$5:$C$1691,2,0) -> 16284 | E16: 1150A | F16: =+VLOOKUP(E16,COLUMNA!$B$5:$C$1691,2,0) -> 37463 | G16: D-8444 | H16: =+VLOOKUP(G16,COLUMNA!$B$5:$C$1691,2,0) -> 16517 | I16: R-8572 | J16: =+VLOOKUP(I16,COLUMNA!$B$5:$C$1691,2,0) -> 14226
A17: 132 | B17: =+VLOOKUP(A17,COLUMNA!$B$5:$C$1691,2,0) -> 8893 | C17: 277 | D17: =+VLOOKUP(C17,COLUMNA!$B$5:$C$1691,2,0) -> 16853 | E17: 1150E | F17: =+VLOOKUP(E17,COLUMNA!$B$5:$C$1691,2,0) -> 35797 | G17: T-8445-R | H17: =+VLOOKUP(G17,COLUMNA!$B$5:$C$1691,2,0) -> 64751 | I17: T-8573 | J17: =+VLOOKUP(I17,COLUMNA!$B$5:$C$1691,2,0) -> 14583
A18: 133 | B18: =+VLOOKUP(A18,COLUMNA!$B$5:$C$1691,2,0) -> 9484 | C18: 278 | D18: =+VLOOKUP(C18,COLUMNA!$B$5:$C$1691,2,0) -> 17362 | E18: 1303 | F18: =+VLOOKUP(E18,COLUMNA!$B$5:$C$1691,2,0) -> 12710 | G18: T-8452 | H18: =+VLOOKUP(G18,COLUMNA!$B$5:$C$1691,2,0) -> 45070 | I18: D-8574 | J18: =+VLOOKUP(I18,COLUMNA!$B$5:$C$1691,2,0) -> 18937
A19: 134 | B19: =+VLOOKUP(A19,COLUMNA!$B$5:$C$1691,2,0) -> 10042 | C19: 279 | D19: =+VLOOKUP(C19,COLUMNA!$B$5:$C$1691,2,0) -> 19631 | E19: 1305 | F19: =+VLOOKUP(E19,COLUMNA!$B$5:$C$1691,2,0) -> 12820 | G19: R-8454 | H19: =+VLOOKUP(G19,COLUMNA!$B$5:$C$1691,2,0) -> 10905 | I19: R-8575 | J19: =+VLOOKUP(I19,COLUMNA!$B$5:$C$1691,2,0) -> 9455
A20: 135 | B20: =+VLOOKUP(A20,COLUMNA!$B$5:$C$1691,2,0) -> 9716 | C20: 280 | D20: =+VLOOKUP(C20,COLUMNA!$B$5:$C$1691,2,0) -> 17776 | E20: 1308 | F20: =+VLOOKUP(E20,COLUMNA!$B$5:$C$1691,2,0) -> 10046 | G20: R-8455 | H20: =+VLOOKUP(G20,COLUMNA!$B$5:$C$1691,2,0) -> 9232 | I20: T-8576 | J20: =+VLOOKUP(I20,COLUMNA!$B$5:$C$1691,2,0) -> 51273
A21: 136 | B21: =+VLOOKUP(A21,COLUMNA!$B$5:$C$1691,2,0) -> 11006 | C21: 281 | D21: =+VLOOKUP(C21,COLUMNA!$B$5:$C$1691,2,0) -> 17055 | E21: 1309 | F21: =+VLOOKUP(E21,COLUMNA!$B$5:$C$1691,2,0) -> 11774 | G21: R-8456 | H21: =+VLOOKUP(G21,COLUMNA!$B$5:$C$1691,2,0) -> 8238 | I21: R-8578 | J21: =+VLOOKUP(I21,COLUMNA!$B$5:$C$1691,2,0) -> 8466
A22: 137 | B22: =+VLOOKUP(A22,COLUMNA!$B$5:$C$1691,2,0) -> 11498 | C22: 282 | D22: =+VLOOKUP(C22,COLUMNA!$B$5:$C$1691,2,0) -> 19053 | E22: 5001R | F22: =+VLOOKUP(E22,COLUMNA!$B$5:$C$1691,2,0) -> 50529 | G22: R-8457 | H22: =+VLOOKUP(G22,COLUMNA!$B$5:$C$1691,2,0) -> 8681 | I22: R-8579 | J22: =+VLOOKUP(I22,COLUMNA!$B$5:$C$1691,2,0) -> 9830
A23: 138 | B23: =+VLOOKUP(A23,COLUMNA!$B$5:$C$1691,2,0) -> 9086 | C23: 283 | D23: =+VLOOKUP(C23,COLUMNA!$B$5:$C$1691,2,0) -> 16441 | E23: 5002 | F23: =+VLOOKUP(E23,COLUMNA!$B$5:$C$1691,2,0) -> 52527 | G23: R-8458 | H23: =+VLOOKUP(G23,COLUMNA!$B$5:$C$1691,2,0) -> 9365 | I23: R-8581 | J23: =+VLOOKUP(I23,COLUMNA!$B$5:$C$1691,2,0) -> 18406
A24: 139 | B24: =+VLOOKUP(A24,COLUMNA!$B$5:$C$1691,2,0) -> 10051 | C24: 284 | D24: =+VLOOKUP(C24,COLUMNA!$B$5:$C$1691,2,0) -> 19129 | E24: 5003R | F24: =+VLOOKUP(E24,COLUMNA!$B$5:$C$1691,2,0) -> 49939 | G24: R-8459 | H24: =+VLOOKUP(G24,COLUMNA!$B$5:$C$1691,2,0) -> 9529 | I24: T-8582 | J24: =+VLOOKUP(I24,COLUMNA!$B$5:$C$1691,2,0) -> 46967
A25: 140 | B25: =+VLOOKUP(A25,COLUMNA!$B$5:$C$1691,2,0) -> 10479 | C25: 285 | D25: =+VLOOKUP(C25,COLUMNA!$B$5:$C$1691,2,0) -> 18434 | E25: 5004 | F25: =+VLOOKUP(E25,COLUMNA!$B$5:$C$1691,2,0) -> 52527 | G25: R-8460 | H25: =+VLOOKUP(G25,COLUMNA!$B$5:$C$1691,2,0) -> 11686 | I25: T-8589 | J25: =+VLOOKUP(I25,COLUMNA!$B$5:$C$1691,2,0) -> 56180
A26: 141 | B26: =+VLOOKUP(A26,COLUMNA!$B$5:$C$1691,2,0) -> 10272 | C26: 286 | D26: =+VLOOKUP(C26,COLUMNA!$B$5:$C$1691,2,0) -> 17516 | E26: 5005 | F26: =+VLOOKUP(E26,COLUMNA!$B$5:$C$1691,2,0) -> 52527 | G26: R-8461 | H26: =+VLOOKUP(G26,COLUMNA!$B$5:$C$1691,2,0) -> 11686 | I26: R-8590 | J26: =+VLOOKUP(I26,COLUMNA!$B$5:$C$1691,2,0) -> 9793
A27: 142 | B27: =+VLOOKUP(A27,COLUMNA!$B$5:$C$1691,2,0) -> 10198 | C27: 287 | D27: =+VLOOKUP(C27,COLUMNA!$B$5:$C$1691,2,0) -> 17070 | E27: 5006 | F27: =+VLOOKUP(E27,COLUMNA!$B$5:$C$1691,2,0) -> 51430 | G27: R-8462 | H27: =+VLOOKUP(G27,COLUMNA!$B$5:$C$1691,2,0) -> 11463 | I27: R-8596 | J27: =+VLOOKUP(I27,COLUMNA!$B$5:$C$1691,2,0) -> 14249
A28: 143 | B28: =+VLOOKUP(A28,COLUMNA!$B$5:$C$1691,2,0) -> 10064 | C28: 288 | D28: =+VLOOKUP(C28,COLUMNA!$B$5:$C$1691,2,0) -> 16894 | E28: 5007R | F28: =+VLOOKUP(E28,COLUMNA!$B$5:$C$1691,2,0) -> 51802 | G28: R-8463 | H28: =+VLOOKUP(G28,COLUMNA!$B$5:$C$1691,2,0) -> 12192 | I28: R-8599 | J28: =+VLOOKUP(I28,COLUMNA!$B$5:$C$1691,2,0) -> 10297
A29: 144 | B29: =+VLOOKUP(A29,COLUMNA!$B$5:$C$1691,2,0) -> 10302 | C29: 289 | D29: =+VLOOKUP(C29,COLUMNA!$B$5:$C$1691,2,0) -> 17362 | E29: 5008 | F29: =+VLOOKUP(E29,COLUMNA!$B$5:$C$1691,2,0) -> 53651 | G29: R-8464 | H29: =+VLOOKUP(G29,COLUMNA!$B$5:$C$1691,2,0) -> 8791 | I29: R-8653 | J29: =+VLOOKUP(I29,COLUMNA!$B$5:$C$1691,2,0) -> 15879
A30: 149R | B30: =+VLOOKUP(A30,COLUMNA!$B$5:$C$1691,2,0) -> 5444 | C30: 291 | D30: =+VLOOKUP(C30,COLUMNA!$B$5:$C$1691,2,0) -> 18321 | E30: 5009 | F30: =+VLOOKUP(E30,COLUMNA!$B$5:$C$1691,2,0) -> 53652 | G30: R-8465 | H30: =+VLOOKUP(G30,COLUMNA!$B$5:$C$1691,2,0) -> 10177 | I30: R-8654 | J30: =+VLOOKUP(I30,COLUMNA!$B$5:$C$1691,2,0) -> 10167
A31: 152 | B31: =+VLOOKUP(A31,COLUMNA!$B$5:$C$1691,2,0) -> 10427 | C31: 292 | D31: =+VLOOKUP(C31,COLUMNA!$B$5:$C$1691,2,0) -> 21520 | E31: 5010 | F31: =+VLOOKUP(E31,COLUMNA!$B$5:$C$1691,2,0) -> 59201 | G31: R-8467 | H31: =+VLOOKUP(G31,COLUMNA!$B$5:$C$1691,2,0) -> 4231 | I31: T-8656 | J31: =+VLOOKUP(I31,COLUMNA!$B$5:$C$1691,2,0) -> 31855
A32: 153 | B32: 10198 | C32: 293 | D32: =+VLOOKUP(C32,COLUMNA!$B$5:$C$1691,2,0) -> 23663 | E32: 5011 | F32: =+VLOOKUP(E32,COLUMNA!$B$5:$C$1691,2,0) -> 55503 | G32: R-8468 | H32: =+VLOOKUP(G32,COLUMNA!$B$5:$C$1691,2,0) -> 9593 | I32: T-8658 | J32: =+VLOOKUP(I32,COLUMNA!$B$5:$C$1691,2,0) -> 53474
A33: 156 | B33: =+VLOOKUP(A33,COLUMNA!$B$5:$C$1691,2,0) -> 8374 | C33: 294 | D33: =+VLOOKUP(C33,COLUMNA!$B$5:$C$1691,2,0) -> 21877 | E33: T-5800 | F33: =+VLOOKUP(E33,COLUMNA!$B$5:$C$1691,2,0) -> 21382 | G33: R-8477 | H33: =+VLOOKUP(G33,COLUMNA!$B$5:$C$1691,2,0) -> 9909 | I33: R-8659 | J33: =+VLOOKUP(I33,COLUMNA!$B$5:$C$1691,2,0) -> 12009
A34: 157PLUS | B34: =+VLOOKUP(A34,COLUMNA!$B$5:$C$1691,2,0) -> 5236 | C34: 295 | D34: =+VLOOKUP(C34,COLUMNA!$B$5:$C$1691,2,0) -> 16760 | E34: T-8095 | F34: =+VLOOKUP(E34,COLUMNA!$B$5:$C$1691,2,0) -> 23370 | G34: R-8481 | H34: =+VLOOKUP(G34,COLUMNA!$B$5:$C$1691,2,0) -> 12652 | I34: T-8660 | J34: =+VLOOKUP(I34,COLUMNA!$B$5:$C$1691,2,0) -> 39293
A35: 158 | B35: =+VLOOKUP(A35,COLUMNA!$B$5:$C$1691,2,0) -> 6484 | C35: 296 | D35: =+VLOOKUP(C35,COLUMNA!$B$5:$C$1691,2,0) -> 29236 | E35: R-8130 | F35: =+VLOOKUP(E35,COLUMNA!$B$5:$C$1691,2,0) -> 9502 | G35: R-8484 | H35: =+VLOOKUP(G35,COLUMNA!$B$5:$C$1691,2,0) -> 14808 | I35: R-8661 | J35: =+VLOOKUP(I35,COLUMNA!$B$5:$C$1691,2,0) -> 11015
A36: 160/60 | B36: =+VLOOKUP(A36,COLUMNA!$B$5:$C$1691,2,0) -> 7131 | C36: 297 | D36: =+VLOOKUP(C36,COLUMNA!$B$5:$C$1691,2,0) -> 17281 | E36: R-8131 | F36: =+VLOOKUP(E36,COLUMNA!$B$5:$C$1691,2,0) -> 9523 | G36: R-8485 | H36: =+VLOOKUP(G36,COLUMNA!$B$5:$C$1691,2,0) -> 17995 | I36: D-8662 | J36: =+VLOOKUP(I36,COLUMNA!$B$5:$C$1691,2,0) -> 17170
A37: 161 | B37: =+VLOOKUP(A37,COLUMNA!$B$5:$C$1691,2,0) -> 9886 | C37: 298 | D37: =+VLOOKUP(C37,COLUMNA!$B$5:$C$1691,2,0) -> 17273 | E37: R-8133 | F37: 10584 | G37: R-8486 | H37: =+VLOOKUP(G37,COLUMNA!$B$5:$C$1691,2,0) -> 17437 | I37: T-8664 | J37: =+VLOOKUP(I37,COLUMNA!$B$5:$C$1691,2,0) -> 23342
A38: 162 | B38: =+VLOOKUP(A38,COLUMNA!$B$5:$C$1691,2,0) -> 10108 | C38: 299 | D38: =+VLOOKUP(C38,COLUMNA!$B$5:$C$1691,2,0) -> 17348 | E38: R-8135 | F38: =+VLOOKUP(E38,COLUMNA!$B$5:$C$1691,2,0) -> 10980 | G38: T-8487 | H38: =+VLOOKUP(G38,COLUMNA!$B$5:$C$1691,2,0) -> 61049 | I38: R-8665 | J38: =+VLOOKUP(I38,COLUMNA!$B$5:$C$1691,2,0) -> 9454
A39: 163 | B39: =+VLOOKUP(A39,COLUMNA!$B$5:$C$1691,2,0) -> 10571 | C39: 407 | D39: =+VLOOKUP(C39,COLUMNA!$B$5:$C$1691,2,0) -> 22421 | E39: D-8175 | F39: =+VLOOKUP(E39,COLUMNA!$B$5:$C$1691,2,0) -> 19759 | G39: D-8489 | H39: =+VLOOKUP(G39,COLUMNA!$B$5:$C$1691,2,0) -> 16092 | I39: R-8666 | J39: =+VLOOKUP(I39,COLUMNA!$B$5:$C$1691,2,0) -> 9731
A40: 164 | B40: =+VLOOKUP(A40,COLUMNA!$B$5:$C$1691,2,0) -> 9595 | C40: 408 | D40: =+VLOOKUP(C40,COLUMNA!$B$5:$C$1691,2,0) -> 25878 | E40: D-8176 | F40: =+VLOOKUP(E40,COLUMNA!$B$5:$C$1691,2,0) -> 22012 | G40: B-8500 | H40: =+VLOOKUP(G40,COLUMNA!$B$5:$C$1691,2,0) -> 26670 | I40: T-8667 | J40: =+VLOOKUP(I40,COLUMNA!$B$5:$C$1691,2,0) -> 42420
...

Sheet COLUMNA
A1: RALUX SAIC | C1: 46220
A2: Referencia | C2: Precio de venta
C3: L268
A5: BOB001-G-90021 | B5: =+VLOOKUP(A5,Hoja1!$A$3:$B$2000,2,0) -> G-90021 | C5: 35723
A6: BOB002-G-90022 | B6: =+VLOOKUP(A6,Hoja1!$A$3:$B$2000,2,0) -> G-90022 | C6: 36640
A7: BOB003-G-90025 | B7: =+VLOOKUP(A7,Hoja1!$A$3:$B$2000,2,0) -> G-90025 | C7: 40502
A8: BOB004-G-90026 | B8: =+VLOOKUP(A8,Hoja1!$A$3:$B$2000,2,0) -> G-90026 | C8: 42132
A9: BOB005-G-90091 | B9: =+VLOOKUP(A9,Hoja1!$A$3:$B$2000,2,0) -> G-90091 | C9: 40540
A10: BOB006-G-90162 | B10: =+VLOOKUP(A10,Hoja1!$A$3:$B$2000,2,0) -> G-90162 | C10: 40503
A11: BOB007-G-90169 | B11: =+VLOOKUP(A11,Hoja1!$A$3:$B$2000,2,0) -> G-90169 | C11: 40504
A12: BOB008-G-90170 | B12: =+VLOOKUP(A12,Hoja1!$A$3:$B$2000,2,0) -> G-90170 | C12: 42340
A13: BOB009-G-90171 | B13: =+VLOOKUP(A13,Hoja1!$A$3:$B$2000,2,0) -> G-90171 | C13: 42339
A14: BOB010-G-91351 | B14: =+VLOOKUP(A14,Hoja1!$A$3:$B$2000,2,0) -> G-91351 | C14: 63209
A15: BOB011-G-91354 | B15: =+VLOOKUP(A15,Hoja1!$A$3:$B$2000,2,0) -> G-91354 | C15: 70663
A16: BOB012-G-91359 | B16: =+VLOOKUP(A16,Hoja1!$A$3:$B$2000,2,0) -> G-91359 | C16: 27946
... A178: BOB179-G-91916 | B178: =+VLOOKUP(A178,Hoja1!$A$3:$B$2000,2,0) -> G-91916 | C178: 57722
A179: BOB180-G-91884 | B179: G-91884 | C179: 43751
A180: BOC001-B-10000 | B180: =+VLOOKUP(A180,Hoja1!$A$3:$B$2000,2,0) -> B-10000 | C180: 34852
A181: BOC002-B-10001 | B181: =+VLOOKUP(A181,Hoja1!$A$3:$B$2000,2,0) -> B-10001 | C181: 31919
A182: BOC003-B-10002 | B182: =+VLOOKUP(A182,Hoja1!$A$3:$B$2000,2,0) -> B-10002 | C182: 30838
A183: BOC004-B-10003 | B183: =+VLOOKUP(A183,Hoja1!$A$3:$B$2000,2,0) -> B-10003 | C183: 67586
A184: BOC005-B-10004 | B184: =+VLOOKUP(A184,Hoja1!$A$3:$B$2000,2,0) -> B-10004 | C184: 60272
A185: BOC006-B-10005 | B185: =+VLOOKUP(A185,Hoja1!$A$3:$B$2000,2,0) -> B-10005 | C185: 70095
A186: BOC007-B-8180 | B186: =+VLOOKUP(A186,Hoja1!$A$3:$B$2000,2,0) -> B-8180 | C186: 27901
A187: BOC008-B-8181 | B187: =+VLOOKUP(A187,Hoja1!$A$3:$B$2000,2,0) -> B-8181 | C187: 18096
A188: BOC009-B-8182 | B188: =+VLOOKUP(A188,Hoja1!$A$3:$B$2000,2,0) -> B-8182 | C188: 25701
A189: BOC010-B-8183 | B189: =+VLOOKUP(A189,Hoja1!$A$3:$B$2000,2,0) -> B-8183 | C189: 17056
A190: BOC011-B-8190 | B190: =+VLOOKUP(A190,Hoja1!$A$3:$B$2000,2,0) -> B-8190 | C190: 32448
A191: BOC012-B-8191 | B191: =+VLOOKUP(A191,Hoja1!$A$3:$B$2000,2,0) -> B-8191 | C191: 27597
... A492: OTR027-V-8820 | B492: =+VLOOKUP(A492,Hoja1!$A$3:$B$2000,2,0) -> V-8820 | C492: 4238
A493: OTR028-V-8821 | B493: V-8821 | C493: 5226
A494: PLA001-PA014100 | B494: =+VLOOKUP(A494,Hoja1!$A$3:$B$2000,2,0) -> PA014100 | C494: 7911
A495: PLA002-PA014200 | B495: =+VLOOKUP(A495,Hoja1!$A$3:$B$2000,2,0) -> PA014200 | C495: 9663
A496: PLA003-PA12475 | B496: =+VLOOKUP(A496,Hoja1!$A$3:$B$2000,2,0) -> PA12475 | C496: 12648
A497: PLA004-PA13137 | B497: =+VLOOKUP(A497,Hoja1!$A$3:$B$2000,2,0) -> PA13137 | C497: 15072
A498: PLA005-PA13153 | B498: =+VLOOKUP(A498,Hoja1!$A$3:$B$2000,2,0) -> PA13153 | C498: 14459
A499: PLA006-PA13293 | B499: =+VLOOKUP(A499,Hoja1!$A$3:$B$2000,2,0) -> PA13293 | C499: 12431
A500: PLA007-PATRIO50A | B500: =+VLOOKUP(A500,Hoja1!$A$3:$B$2000,2,0) -> PATRIO50A | C500: 9787
A501: PLA008-PP12441 | B501: =+VLOOKUP(A501,Hoja1!$A$3:$B$2000,2,0) -> PP12441 | C501: 17732
A502: PLA009-PP12442 | B502: =+VLOOKUP(A502,Hoja1!$A$3:$B$2000,2,0) -> PP12442 | C502: 19404
...

Sheet Hoja1
A1: NOMBRE DEL PRODUCTO | B1: CODIGO
A2: Name | B2: VTAS
A3: REL001-103 | B3: 103
A4: REL002-104 | B4: 104
A5: REL003-106 | B5: 106
A6: REL004-107 | B6: 107
A7: REL005-109 | B7: 109
A8: REL006-110 | B8: 110
A9: REL007-111 | B9: 111
A10: REL008-112 | B10: 112
A11: REL009-127 | B11: 127
A12: REL010-130 | B12: 130
A13: REL011-132 | B13: 132
A14: REL012-133 | B14: 133
... A123: TEM014-1006605 | B123: 1006605
A124: OTR012-1150A | B124: 1150A
A125: OTR013-1150E | B125: 1150E
A126: REL045-149R | B126: 149R
A127: REL046-157PLUS | B127: 157PLUS
A128: REL047-160/60 | B128: 160/60
A129: REL048-168R | B129: 168R
A130: REL049-170R | B130: 170R
A131: DES033-211E | B131: 211E
A132: DES034-222E | B132: 222E
A133: DES035-222M | B133: 222M
A134: DES036-224E | B134: 224E
A135: DES037-244E | B135: 244E
... A989: REL244-RGC-9181 | B989: RGC-9181
A990: REL245-113 | B990: 113
A991: TEM015-806 | B991: 806
A992: TEM016-818 | B992: 818
A993: TEM017-T-10048 | B993: T-10048
A994: TEM018-T-10065 | B994: T-10065
A995: OTR019-T-1302 | B995: T-1302
A996: OTR020-T-1304 | B996: T-1304
A997: OTR021-T-5800 | B997: T-5800
A998: OTR022-T-8095 | B998: T-8095
A999: TEM019-T-8426 | B999: T-8426
A1000: TEM020-T-8428 | B1000: T-8428
A1001: PRE012-T-8445-R | B1001: T-8445-R
...
