Workbook

Sheet Productos
A1: eliminar | B1: id | C1: codigo_ralux | D1: producto_tipo_id | E1: descripcion_es | F1: precio | G1: descuento | H1: voltaje | I1: amperaje | J1: terminales | K1: soporte | L1: caract_1 | M1: valor_1 | N1: caract_2 | O1: valor_2 | P1: caract_3 | Q1: valor_3 | R1: caract_4 | S1: valor_4 | T1: caract_5 | U1: valor_5 | V1: caract_6 | W1: valor_6 | X1: caract_7 | Y1: valor_7 | Z1: caract_8 | AA1: valor_8 | AB1: caract_9 | AC1: valor_9 | AD1: caract_10 | AE1: valor_10 | AF1: destacado | AG1: visible | AH1: orden | AI1: vehiculo_tipos_ids | AJ1: marcas_ids | AK1: modelos_ids | AL1: codigos_om
A2: A VALIDAR | B2: 1350 | C2: T-9200 | D2: 14 | E2: Temporizador de Parada solicitada | F2: =VLOOKUP(Productos!C2,PRECIOS!$A$5:$C$1031,3,FALSE) -> 67660 | G2: 0 | H2: 24 | I2: 10 | K2: 1 | AG2: 1 | AI2: 11 | AK2: 1593
B3: 1302 | C3: FMI023200 | D3: 21 | E3: Regulador de voltaje | F3: =VLOOKUP(Productos!C3,PRECIOS!$A$5:$C$1031,3,FALSE) -> 35166 | G3: 0 | H3: 12 | AG3: 1 | AI3: 4 | AJ3: 87 | AK3: 101,102,110 | AL3: A866X23200|87
B4: 1334 | C4: R-10062 | D4: 14 | E4: Relé multifunción | F4: =VLOOKUP(Productos!C4,PRECIOS!$A$5:$C$1031,3,FALSE) -> 10163 | G4: 0 | H4: 12 | J4: 5 | AG4: 1 | AI4: 4 | AJ4: 51 | AK4: 1906,1907 | AL4: A0025421419|51
B5: 1335 | C5: R-10063 | D5: 14 | E5: Relé multifunción | F5: =VLOOKUP(Productos!C5,PRECIOS!$A$5:$C$1031,3,FALSE) -> 9232 | G5: 0 | H5: 12 | J5: 5 | AG5: 1 | AI5: 4 | AJ5: 47 | AK5: 132,1299,1709 | AL5: 13266315|47
B6: 1336 | C6: R-10064 | D6: 14 | E6: Relé multifunción | F6: =VLOOKUP(Productos!C6,PRECIOS!$A$5:$C$1031,3,FALSE) -> 12877 | G6: 0 | H6: 12 | J6: 4 | AG6: 1 | AI6: 4 | AJ6: 47 | AK6: 126,129,1811 | AL6: 90494959|47
B7: 1337 | C7: T-10065 | D7: 16 | E7: Temporizador | F7: =VLOOKUP(Productos!C7,PRECIOS!$A$5:$C$1031,3,FALSE) -> 18784 | G7: 0 | H7: 12 | J7: 3 | AG7: 1 | AI7: 6 | AJ7: 51 | AK7: 147 | AL7: A3845427023|51
B8: 1338 | C8: R-10010 | D8: 14 | E8: Relé multifunción | F8: =VLOOKUP(Productos!C8,PRECIOS!$A$5:$C$1031,3,FALSE) -> 9320 | G8: 0 | H8: 12 | J8: 4 | AG8: 1 | AI8: 4 | AJ8: 74 | AK8: 270,553,1577 | AL8: 90987-02012|74
B9: 1339 | C9: R-10011 | D9: 14 | E9: Relé multifunción | F9: =VLOOKUP(Productos!C9,PRECIOS!$A$5:$C$1031,3,FALSE) -> 7285 | G9: 0 | H9: 12 | J9: 4 | AG9: 1 | AI9: 4 | AJ9: 74 | AK9: 1876,1880 | AL9: 90987-02028|74
B10: 1340 | C10: R-10019 | D10: 14 | E10: Relé multifunción | F10: =VLOOKUP(Productos!C10,PRECIOS!$A$5:$C$1031,3,FALSE) -> 9156 | G10: 0 | H10: 12 | J10: 5 | AG10: 1 | AI10: 4 | AJ10: 74 | AK10: 553,1491,1577,1880 | AL10: 156700-1062|74,88263-32070|74,90080-87009|74,90080-87012|74,90080-8720|74,90084-98032|74,90987-04004|74
B11: 1342 | C11: R-10025 | D11: 14 | E11: Relé multifunción | F11: =VLOOKUP(Productos!C11,PRECIOS!$A$5:$C$1031,3,FALSE) -> 8791 | G11: 0 | H11: 12 | J11: 4 | AG11: 1 | AI11: 4 | AJ11: 74 | AK11: 553,971 | AL11: 90987-02020|74
B12: 1343 | C12: R-10026 | D12: 14 | E12: Relé multifunción | F12: =VLOOKUP(Productos!C12,PRECIOS!$A$5:$C$1031,3,FALSE) -> 13905 | G12: 0 | H12: 12 | J12: 4 | AG12: 1 | AI12: 4 | AJ12: 74 | AK12: 1107,1281,1577 | AL12: 90987-02025|74
B13: 1345 | C13: R-10028 | D13: 14 | E13: Relé multifunción | F13: =VLOOKUP(Productos!C13,PRECIOS!$A$5:$C$1031,3,FALSE) -> 13354 | G13: 0 | H13: 12 | J13: 4 | AG13: 1 | AI13: 4 | AJ13: 74 | AK13: 553 | AL13: 90987-02030|74
B14: 1346 | C14: R-10029 | D14: 14 | E14: Relé multifunción | F14: =VLOOKUP(Productos!C14,PRECIOS!$A$5:$C$1031,3,FALSE) -> 11740 | G14: 0 | H14: 12 | J14: 5 | AG14: 1 | AI14: 4 | AJ14: 74 | AK14: 553 | AL14: 90987-04006|74
B15: 1347 | C15: R-10030 | D15: 14 | E15: Relé multifunción | F15: =VLOOKUP(Productos!C15,PRECIOS!$A$5:$C$1031,3,FALSE) -> 13244 | G15: 0 | H15: 12 | J15: 5 | AG15: 1 | AI15: 4 | AJ15: 74 | AK15: 1880 | AL15: 90987-04010|74
B16: 1348 | C16: R-10032 | D16: 14 | E16: Relé multifunción | F16: =VLOOKUP(Productos!C16,PRECIOS!$A$5:$C$1031,3,FALSE) -> 13208 | G16: 0 | H16: 12 | J16: 4 | AG16: 1 | AI16: 4 | AJ16: 74 | AK16: 1712 | AL16: 90987-T2002|74
B17: 1349 | C17: R-10033 | D17: 14 | E17: Relé multifunción | F17: =VLOOKUP(Productos!C17,PRECIOS!$A$5:$C$1031,3,FALSE) -> 13244 | G17: 0 | H17: 12 | J17: 5 | AG17: 1 | AI17: 4 | AJ17: 74 | AK17: 1452 | AL17: 90987-T2003|74
B18: 1333 | C18: R-10061 | D18: 14 | E18: Relé multifunción | F18: =VLOOKUP(Productos!C18,PRECIOS!$A$5:$C$1031,3,FALSE) -> 13464 | G18: 0 | H18: 12 | J18: 4 | AG18: 1 | AI18: 4 | AJ18: 51 | AK18: 1906,1907 | AL18: A0025422619|51
B19: 1351 | C19: RGC-9181 | D19: 14 | E19: Relay con sensor de carga para batería auxiliar | F19: =VLOOKUP(Productos!C19,PRECIOS!$A$5:$C$1031,3,FALSE) -> 75208 | G19: 0 | H19: 12 | I19: 120 | J19: 6356 | K19: 1 | AG19: 1 | AI19: 4 | AK19: 350
B20: 1352 | C20: R-9032-R | D20: 16 | E20: Rele de inyección | F20: =VLOOKUP(Productos!C20,PRECIOS!$A$5:$C$1031,3,FALSE) -> 19307 | G20: 0 | H20: 12 | J20: 15 | K20: 1 | AG20: 1 | AI20: 4 | AK20: 167
B21: 1353 | C21: R-10066 | D21: 14 | E21: Relé multifunción | F21: =VLOOKUP(Productos!C21,PRECIOS!$A$5:$C$1031,3,FALSE) -> 12474 | G21: 0 | H21: 12 | I21: 70 | J21: 4 | AG21: 1 | AI21: 4 | AK21: 204,933,1017,1263,1483,1636,1683,1688,1721,1910
B22: 1354 | C22: R-10067 | D22: 14 | E22: Multifunción | F22: =VLOOKUP(Productos!C22,PRECIOS!$A$5:$C$1031,3,FALSE) -> 8714 | G22: 0 | H22: 12 | I22: 20 | J22: 5 | AG22: 1 | AI22: 4 | AJ22: 52 | AK22: 1111,1321,2050,2051 | AL22: 9673062180|52
B23: 1355 | C23: R-10068 | D23: 14 | E23: Multifunción | F23: =VLOOKUP(Productos!C23,PRECIOS!$A$5:$C$1031,3,FALSE) -> 12291 | G23: 0 | H23: 12 | J23: 4 | AG23: 1 | AI23: 4 | AK23: 170
B24: 1356 | C24: R-10070 | D24: 14 | E24: Multifunción | F24: =VLOOKUP(Productos!C24,PRECIOS!$A$5:$C$1031,3,FALSE) -> 17036 | G24: 0 | H24: 12 | J24: 15 | K24: 1 | AG24: 1 | AI24: 4 | AJ24: 187 | AK24: 170,1758 | AL24: 9607540680|187
B25: 1357 | C25: R-10071 | D25: 14 | E25: RELE DE INYECCION | F25: =VLOOKUP(Productos!C25,PRECIOS!$A$5:$C$1031,3,FALSE) -> 21089 | G25: 0 | H25: 12 | J25: 15 | K25: 1 | AG25: 1 | AI25: 4 | AJ25: 52,187 | AK25: 57,173,177,179,1282,1321 | AL25: 9627109680|52,9664883180|52,9627109680|187,9664883180|187
B26: 1358 | C26: R-10072 | D26: 14 | E26: Rele de inyeccion | F26: =VLOOKUP(Productos!C26,PRECIOS!$A$5:$C$1031,3,FALSE) -> 16694 | G26: 0 | H26: 12 | J26: 15 | K26: 1 | AG26: 1 | AI26: 4 | AJ26: 45 | AK26: 70,83,84,86,256,892,1601 | AL26: 46414605|45,77317510|45,7767971|45
B27: 1359 | C27: FMI028095 | D27: 21 | E27: Regulador de voltaje con sensado y lámpara | F27: =VLOOKUP(Productos!C27,PRECIOS!$A$5:$C$1031,3,FALSE) -> 40301 | G27: 0 | H27: 24 | J27: 3 | AG27: 1 | AI27: 6 | AJ27: 45,87,110,116,120 | AK27: 141 | AL27: 504028095 504028095 504065776 504282333 504286394 504349338 5043493381|45,543228c|87,A004T8491 A004TA0591 A004TA0592 A004TA8491 A004TA8492 A004TA8492AM A004TA8494 A4TA0592 A4TA0593 A4TA8492|87,8600399|110,063535255000|116,860706GB 860706GBA 860712GB 860712GBA|120
B28: 1360 | C28: R-10069 | D28: 14 | E28: Multifunción | F28: =VLOOKUP(Productos!C28,PRECIOS!$A$5:$C$1031,3,FALSE) -> 9128 | G28: 0 | H28: 12 | J28: 4 | AG28: 1 | AI28: 4 | AJ28: 187 | AK28: 1908,2051 | AL28: 980792780|187
B29: 1361 | C29: 5003R | D29: 18 | E29: Precalentado diesel micro controlado | F29: =VLOOKUP(Productos!C29,PRECIOS!$A$5:$C$1031,3,FALSE) -> 47464 | G29: 0 | H29: 12 | I29: 60 | J29: 6 | K29: 1 | AG29: 1 | AI29: 4 | AJ29: 52 | AK29: 162,164,166,646,647,1944,1945,1946,1947 | AL29: 5981110|52,9251586780|52
B30: 1362 | C30: 5001R | D30: 18 | E30: Precalentado diesel micro controlado | F30: =VLOOKUP(Productos!C30,PRECIOS!$A$5:$C$1031,3,FALSE) -> 48024 | G30: 0 | H30: 12 | I30: 60 | J30: 6 | K30: 1 | AG30: 1 | AI30: 4 | AJ30: 45 | AK30: 70,71,401,1601,1940 | AL30: 5973754|45,5973757|45,7765674|45,94002142|45
B31: 1363 | C31: 5007R | D31: 18 | E31: Precalentado diesel micro controlado | F31: =VLOOKUP(Productos!C31,PRECIOS!$A$5:$C$1031,3,FALSE) -> 49234 | G31: 0 | H31: 12 | J31: 6 | K31: 1 | AG31: 1 | AI31: 4 | AJ31: 53 | AK31: 188,192,196,337,1948,1949 | AL31: 7700757776|53,7702089784|53
B32: 1364 | C32: B-9102 BI VOLTAJE 12/24V | D32: 17 | E32: BOCINA DE RETROMARCHA 12/24V (BIVOLTAJE) REEMPLAZO DE B-9100 Y B-9101 | F32: 17619 | G32: 0 | H32: 1224 | I32: 170 | K32: 1 | AG32: 1 | AI32: 4,6 | AK32: 362,1336
B33: 1318 | C33: R-10043 | D33: 14 | E33: Fusilera interior | F33: =VLOOKUP(Productos!C33,PRECIOS!$A$5:$C$1031,3,FALSE) -> 9847 | G33: 0 | H33: 12 | AG33: 1 | AI33: 4 | AJ33: 72 | AK33: 489,502,1274,1329,1800 | AL33: 94580702|72
B34: 1303 | C34: FPR1652 | D34: 21 | E34: Regulador de voltaje | F34: =VLOOKUP(Productos!C34,PRECIOS!$A$5:$C$1031,3,FALSE) -> 26766 | G34: 0 | H34: 12 | AG34: 1 | AI34: 4 | AJ34: 109,114,118 | AK34: 197,201,1930 | AL34: UB223|109,092937|114,092982|114,300725|114,300883|114,YH 2606|118
B35: 1304 | C35: FNA321401 | D35: 21 | E35: Regulador de voltaje | F35: =VLOOKUP(Productos!C35,PRECIOS!$A$5:$C$1031,3,FALSE) -> 21102 | G35: 0 | H35: 12 | AG35: 1 | AI35: 4 | AJ35: 127 | AK35: 1336,1928,1931 | AL35: 3214000001|127
B36: 1305 | C36: FPR1925 | D36: 21 | E36: Regulador de voltaje | F36: =VLOOKUP(Productos!C36,PRECIOS!$A$5:$C$1031,3,FALSE) -> 24616 | G36: 0 | H36: 12 | AG36: 1 | AI36: 4 | AJ36: 41,118 | AK36: 194,563,565,1933,1934 | AL36: 5761|,56|41,YH 1925|118,YH 1933|118
A37: MODIFICADO | B37: 1306 | C37: 819 | D37: 16 | E37: Destallador parabrisas | F37: =VLOOKUP(Productos!C37,PRECIOS!$A$5:$C$1031,3,FALSE) -> #N/A | G37: 0 | H37: 12 | J37: 6 | AG37: 1 | AI37: 4 | AJ37: 41,52 | AK37: 54,56,166,592,1055 | AL37: 6555300|41,9753498780|41,6555300|52,9753498780|52,975349880|52
B38: 1307 | C38: T-8504 | D38: 16 | E38: Interfase nivel combustible | F38: =VLOOKUP(Productos!C38,PRECIOS!$A$5:$C$1031,3,FALSE) -> #N/A | G38: 0 | H38: 12 | J38: 5 | AG38: 1 | AI38: 4 | AJ38: 53 | AK38: 195 | AL38: 7702218650|53
B39: 1308 | C39: D-9176 | D39: 15 | E39: Giro - Baliza | F39: =VLOOKUP(Productos!C39,PRECIOS!$A$5:$C$1031,3,FALSE) -> 15445 | G39: 0 | H39: 12 | J39: 3 | AG39: 1 | AI39: 4 | AJ39: 45 | AK39: 83,84 | AL39: 51926128|45
B40: 1309 | C40: 136 | D40: 14 | E40: Luneta térmica - Alzacristales - Aire acondicionado - Faros | F40: =VLOOKUP(Productos!C40,PRECIOS!$A$5:$C$1031,3,FALSE) -> 10309 | G40: 0 | H40: 12 | J40: 4 | AG40: 1 | AI40: 4 | AJ40: 42 | AK40: 1055,1336,1971 | AL40: 123456789012|42
...

Sheet PRECIOS
A1: RALUX SAIC
A2: LISTA DE PRECIOS Nº 267
A4: ART | C4: LISTA
A5: 103 | B5: REL001-103 | C5: 20617
A6: 104 | B6: REL002-104 | C6: 19431
A7: 106 | B7: REL003-106 | C7: 20311
A8: 107 | B8: REL004-107 | C8: 21380
A9: 109 | B9: REL005-109 | C9: 22831
A10: 110 | B10: REL006-110 | C10: 22258
A11: 111 | B11: REL007-111 | C11: 22300
A12: 112 | B12: REL008-112 | C12: 22986
A13: 113 | B13: REL245-113 | C13: 24687
A14: 128 | B14: REL250-128 | C14: 10434
A15: 129 | B15: REL247-129 | C15: 10750
A16: 130 | B16: REL010-130 | C16: 10382
... A29: 144 | B29: REL023-144 | C29: 9593
A30: 149R | B30: REL045-149R | C30: 4974
A31: 152 | B31: REL024-152 | C31: 9711
A32: 153 | B32: REL251-153 | C32: 9495
A33: 156 | B33: REL025-156 | C33: 8003
A34: 157PLUS | B34: REL046-157PLUS | C34: 4733
A35: 158 | B35: REL026-158 | C35: 5982
A36: 160/60 | B36: REL047-160/60 | C36: 6530
A37: 161 | B37: REL027-161 | C37: 9290
A38: 162 | B38: REL028-162 | C38: 9502
A39: 163 | B39: REL029-163 | C39: 9847
A40: 164 | B40: REL030-164 | C40: 8924
A41: 165 | B41: REL031-165 | C41: 7702
A42: 166 | B42: REL032-166 | C42: 9847
A43: 168R | B43: REL048-168R | C43: 6567
A44: 170R | B44: REL049-170R | C44: 7199
A45: 173 | B45: REL033-173 | C45: 5980
A46: 174 | B46: REL034-174 | C46: 8864
A47: 177 | B47: REL035-177 | C47: 8968
A48: 178 | B48: REL036-178 | C48: 9846
A49: 184 | B49: REL037-184 | C49: 11869
A50: 185 | B50: REL038-185 | C50: 8298
A51: 186 | B51: REL039-186 | C51: 9686
A52: 188 | B52: REL040-188 | C52: 9145
A53: 189 | B53: REL041-189 | C53: 9846
...

Sheet Ref - Vehiculo Tipos
A1: id | B1: descripcion_es
A2: 4 | B2: Automovil
A3: 5 | B3: Motos
A4: 6 | B4: Camion
A5: 7 | B5: Tractor
A6: 8 | B6: Furgon
A7: 10 | B7: Camioneta
A8: 11 | B8: Colectivos
A9: 13 | B9: Nielson
A10: 14 | B10: Man

Sheet Ref - Marcas
A1: id | B1: descripcion_es | C1: vehiculo_tipo_id | D1: vehiculo_tipo
A2: 59
A3: 60
A4: 61
A5: 63
A6: 73
A7: 76
A8: 81
A9: 117
A10: 135
A11: 138
A12: 140
A13: 141
A14: 142
A15: 134 | B15: -
A16: 166 | B16: Acura
A17: 205 | B17: Agco
A18: 164 | B18: Agrale
A19: 176 | B19: Airtex
A20: 69 | B20: Alfa-Romeo
A21: 130 | B21: Argelite
A22: 70 | B22: Audi
A23: 137 | B23: Beru
A24: 42 | B24: BMW
A25: 107 | B25: Bosch
A26: 152 | B26: Bougicord
... A163: 195 | B163: Zanello

Sheet Ref - Modelos
A1: id | B1: descripcion_es | C1: marca_id | D1: marca
A2: 1720 | B2: Logan (nuevo) | C2: 53 | D2: Renault
A3: 1580 | B3: - | C3: 90 | D3: Porsche
A4: 1581 | B4: - | C4: 42 | D4: BMW
A5: 1582 | B5: - | C5: 70 | D5: Audi
A6: 1583 | B6: - | C6: 55 | D6: Volkswagen
A7: 1584 | B7: - | C7: 56 | D7: Volvo
A8: 1593 | B8: - | C8: 51 | D8: Mercedes Benz
A9: 1601 | B9: - | C9: 45 | D9: Fiat
A10: 1608 | B10: - | C10: 113 | D10: Nissan
A11: 1637 | B11: - | C11: 157 | D11: Hyundai
A12: 1638 | B12: - | C12: 175 | D12: KIA
A13: 1645 | B13: - | C13: 74 | D13: Toyota
... A25: 1502 | B25: 1.8, 2.0 | C25: 78 | D25: Daewoo
A26: 425 | B26: 10 | C26: 72 | D26: Chevrolet
A27: 766 | B27: 100-PT-50 | C27: 97 | D27: Siambreta
A28: 577 | B28: 1000 | C28: 86 | D28: Dodge
A29: 170 | B29: 106 | C29: 52 | D29: Peugeot
A30: 270 | B30: 106 1.5 | C30: 52 | D30: Peugeot
A31: 1761 | B31: 106 16V Motor TUS14 | C31: 52 | D31: Peugeot
A32: 1926 | B32: 1075 | C32: 65 | D32: Massey-Ferguson
A33: 388 | B33: 1075 | C33: 67 | D33: Ferguson
A34: 793 | B34: 110-Swing-RR | C34: 99 | D34: Zanella
A35: 63 | B35: 1100 | C35: 45 | D35: Fiat
A36: 392 | B36: 1112 | C36: 51 | D36: Mercedes Benz
A37: 393 | B37: 1114 | C37: 51 | D37: Mercedes Benz
A38: 397 | B38: 113 | C38: 54 | D38: Scania
A39: 947 | B39: 121 1.2i 16V | C39: 148 | D39: Mazda
A40: 64 | B40: 125 | C40: 45 | D40: Fiat
A41: 824 | B41: 125-Custom | C41: 103 | D41: Motomel
A42: 814 | B42: 125-Luxe- | C42: 101 | D42: Kymco
A43: 815 | B43: 125-Pulsar-CK | C43: 101 | D43: Kymco
A44: 813 | B44: 125-Pulsar-DC | C44: 101 | D44: Kymco
A45: 803 | B45: 125-QM7B | C45: 100 | D45: Gilera
A46: 840 | B46: 125-Spike | C46: 79 | D46: Suzuki
A47: 839 | B47: 125-Spike-R | C47: 79 | D47: Suzuki
A48: 829 | B48: 125-Top | C48: 103 | D48: Motomel
A49: 65 | B49: 128 | C49: 45 | D49: Fiat
A50: 81 | B50: 128-E | C50: 45 | D50: Fiat
A51: 886 | B51: 13 | C51: 138
...

Sheet Ref - Producto Tipos
A1: id | B1: descripcion_es
A2: 36 | B2: Destelladores electromecanicos de carga variable
A3: 54 | B3: Bobinas
A4: 53 | B4: Rele de inyección
A5: 51 | B5: Destelladores electromecánicos
A6: 50 | B6: Placas Portadiodos
A7: 49 | B7: Bombas de combustible
A8: 48 | B8: Plaquetas Rectificadoras
A9: 46 | B9: Probador de Bobinas de Ignicion
A10: 45 | B10: Probador de Reguladores de Voltaje
A11: 44 | B11: Probador de Modulos de Ignicion
A12: 43 | B12: Multimetros Digitales
A13: 42 | B13: Linterna
... A31: 14 | B31: Relays
